---
title: "Re: Exception: {\"phase\":0,\"error\":\"[timeout]"
description: ""
project: community
lastmod: 2013-01-31T05:16:56-08:00
sitemap:
  priority: 0.2
layout: mailinglistitem
mailinglist_id: "msg09939"
mailinglist_parent_id: "msg09919"
author_name: "David Montgomery"
project_section: "mailinglistitem"
sent_date: 2013-01-31T05:16:56-08:00
---


Yeah...the update using the ubuntu package worked! Whew! scary....

See Ya


On Wed, Jan 30, 2013 at 6:07 PM, David Montgomery  wrote:

&gt; If I build from source will that solve the problem? Else....how can i get
&gt; the data out so I can use hadoop?
&gt;
&gt; I am using ubuntu. Do I just build on new machines and point my volume
&gt; attachment where data is stored to the new nodes?
&gt;
&gt;
&gt;
&gt;
&gt; On Fri, Jan 25, 2013 at 10:04 AM, Matt Black wrote:
&gt;
&gt;&gt; Hi David,
&gt;&gt;
&gt;&gt; This is a known error that has been resolved in trunk, but is yet to be
&gt;&gt; released:
&gt;&gt;
&gt;&gt; https://github.com/basho/riak\\_kv/issues/290
&gt;&gt;
&gt;&gt; Any word on a release date, Basho guys?
&gt;&gt;
&gt;&gt;
&gt;&gt; On 25 January 2013 12:52, David Montgomery wrote:
&gt;&gt;
&gt;&gt;&gt; Hi,
&gt;&gt;&gt;
&gt;&gt;&gt; Why will riak throw this type of exception when I have a timeout of
&gt;&gt;&gt; TIMEOUT=3000000?
&gt;&gt;&gt;
&gt;&gt;&gt; What does this error mean?
&gt;&gt;&gt;
&gt;&gt;&gt; How of now I cant get data out of a production system.
&gt;&gt;&gt;
&gt;&gt;&gt;
&gt;&gt;&gt;
&gt;&gt;&gt;
&gt;&gt;&gt; 'Traceback (most recent call last):
&gt;&gt;&gt; File "gg.py", line 324, in 
&gt;&gt;&gt; results =
&gt;&gt;&gt; getDomainReportIndex(bucket=bucket,date\\_start=int(utc\\_start\\_date),date\\_end=int(utc\\_end\\_date))
&gt;&gt;&gt; File "gg.py", line 137, in getDomainReportIndex
&gt;&gt;&gt; for result in query.run(timeout=TIMEOUT):
&gt;&gt;&gt; File
&gt;&gt;&gt; "/usr/local/lib/python2.7/dist-packages/riak-1.5.1-py2.7.egg/riak/mapreduce.py",
&gt;&gt;&gt; line 234, in run
&gt;&gt;&gt; result = t.mapred(self.\\_inputs, query, timeout)
&gt;&gt;&gt; File
&gt;&gt;&gt; "/usr/local/lib/python2.7/dist-packages/riak-1.5.1-py2.7.egg/riak/transports/pbc.py",
&gt;&gt;&gt; line 454, in mapred
&gt;&gt;&gt; \\_handle\\_response)
&gt;&gt;&gt; File
&gt;&gt;&gt; "/usr/local/lib/python2.7/dist-packages/riak-1.5.1-py2.7.egg/riak/transports/pbc.py",
&gt;&gt;&gt; line 548, in send\\_msg\\_multi
&gt;&gt;&gt; msg\\_code, resp = self.recv\\_msg(conn, expect)
&gt;&gt;&gt; File
&gt;&gt;&gt; "/usr/local/lib/python2.7/dist-packages/riak-1.5.1-py2.7.egg/riak/transports/pbc.py",
&gt;&gt;&gt; line 589, in recv\\_msg
&gt;&gt;&gt; raise Exception(msg.errmsg)
&gt;&gt;&gt; Exception:
&gt;&gt;&gt; {"phase":0,"error":"[timeout]","input":"{&lt;&lt;\\"impressions\\"&gt;&gt;,&lt;&lt;\\"322c0473-9eeb-4c9c-81fe-4e898bc50416:cid5989410021:agid7744464312:2012122316:SG\\"&gt;&gt;}","type":"forward\\_preflist","stack":"[]"}
&gt;&gt;&gt;
&gt;&gt;&gt;
&gt;&gt;&gt; \\_\\_\\_\\_\\_\\_\\_\\_\\_\\_\\_\\_\\_\\_\\_\\_\\_\\_\\_\\_\\_\\_\\_\\_\\_\\_\\_\\_\\_\\_\\_\\_\\_\\_\\_\\_\\_\\_\\_\\_\\_\\_\\_\\_\\_\\_\\_
&gt;&gt;&gt; riak-users mailing list
&gt;&gt;&gt; riak-users@lists.basho.com
&gt;&gt;&gt; http://lists.basho.com/mailman/listinfo/riak-users\\_lists.basho.com
&gt;&gt;&gt;
&gt;&gt;&gt;
&gt;&gt;
&gt;
\\_\\_\\_\\_\\_\\_\\_\\_\\_\\_\\_\\_\\_\\_\\_\\_\\_\\_\\_\\_\\_\\_\\_\\_\\_\\_\\_\\_\\_\\_\\_\\_\\_\\_\\_\\_\\_\\_\\_\\_\\_\\_\\_\\_\\_\\_\\_
riak-users mailing list
riak-users@lists.basho.com
http://lists.basho.com/mailman/listinfo/riak-users\\_lists.basho.com

